{
 "cells": [
  {
   "cell_type": "code",
   "execution_count": 1,
   "metadata": {},
   "outputs": [
    {
     "name": "stderr",
     "output_type": "stream",
     "text": [
      "C:\\Users\\Sehwan Yoo\\.conda\\envs\\tf1.15\\lib\\site-packages\\ale_py\\roms\\utils.py:90: DeprecationWarning: SelectableGroups dict interface is deprecated. Use select.\n",
      "  for external in metadata.entry_points().get(self.group, []):\n",
      "ERROR:root:Internal Python error in the inspect module.\n",
      "Below is the traceback from this internal error.\n",
      "\n",
      "ERROR:root:Internal Python error in the inspect module.\n",
      "Below is the traceback from this internal error.\n",
      "\n",
      "ERROR:root:Internal Python error in the inspect module.\n",
      "Below is the traceback from this internal error.\n",
      "\n"
     ]
    },
    {
     "name": "stdout",
     "output_type": "stream",
     "text": [
      "Traceback (most recent call last):\n",
      "  File \"C:\\Users\\Sehwan Yoo\\.conda\\envs\\tf1.15\\lib\\site-packages\\IPython\\core\\interactiveshell.py\", line 3457, in run_code\n",
      "    exec(code_obj, self.user_global_ns, self.user_ns)\n",
      "  File \"C:\\Users\\SEHWAN~1\\AppData\\Local\\Temp/ipykernel_43336/3479638839.py\", line 1, in <module>\n",
      "    from stable_baselines.common.atari_wrappers import make_atari, wrap_deepmind\n",
      "  File \"C:\\Users\\Sehwan Yoo\\.conda\\envs\\tf1.15\\lib\\site-packages\\stable_baselines\\__init__.py\", line 7, in <module>\n",
      "    from stable_baselines.deepq import DQN\n",
      "  File \"C:\\Users\\Sehwan Yoo\\.conda\\envs\\tf1.15\\lib\\site-packages\\stable_baselines\\deepq\\__init__.py\", line 1, in <module>\n",
      "    from stable_baselines.deepq.policies import MlpPolicy, CnnPolicy, LnMlpPolicy, LnCnnPolicy\n",
      "  File \"C:\\Users\\Sehwan Yoo\\.conda\\envs\\tf1.15\\lib\\site-packages\\stable_baselines\\deepq\\policies.py\", line 2, in <module>\n",
      "    import tensorflow.contrib.layers as tf_layers\n",
      "  File \"C:\\Users\\Sehwan Yoo\\.conda\\envs\\tf1.15\\lib\\site-packages\\tensorflow\\__init__.py\", line 50, in __getattr__\n",
      "    module = self._load()\n",
      "  File \"C:\\Users\\Sehwan Yoo\\.conda\\envs\\tf1.15\\lib\\site-packages\\tensorflow\\__init__.py\", line 44, in _load\n",
      "    module = _importlib.import_module(self.__name__)\n",
      "  File \"C:\\Users\\Sehwan Yoo\\.conda\\envs\\tf1.15\\lib\\importlib\\__init__.py\", line 127, in import_module\n",
      "    return _bootstrap._gcd_import(name[level:], package, level)\n",
      "  File \"C:\\Users\\Sehwan Yoo\\.conda\\envs\\tf1.15\\lib\\site-packages\\tensorflow_core\\contrib\\__init__.py\", line 39, in <module>\n",
      "    from tensorflow.contrib import compiler\n",
      "  File \"C:\\Users\\Sehwan Yoo\\.conda\\envs\\tf1.15\\lib\\site-packages\\tensorflow_core\\contrib\\compiler\\__init__.py\", line 21, in <module>\n",
      "    from tensorflow.contrib.compiler import jit\n",
      "  File \"C:\\Users\\Sehwan Yoo\\.conda\\envs\\tf1.15\\lib\\site-packages\\tensorflow_core\\contrib\\compiler\\__init__.py\", line 22, in <module>\n",
      "    from tensorflow.contrib.compiler import xla\n",
      "  File \"C:\\Users\\Sehwan Yoo\\.conda\\envs\\tf1.15\\lib\\site-packages\\tensorflow_core\\contrib\\compiler\\xla.py\", line 22, in <module>\n",
      "    from tensorflow.python.estimator import model_fn as model_fn_lib\n",
      "  File \"C:\\Users\\Sehwan Yoo\\.conda\\envs\\tf1.15\\lib\\site-packages\\tensorflow_core\\python\\estimator\\model_fn.py\", line 26, in <module>\n",
      "    from tensorflow_estimator.python.estimator import model_fn\n",
      "  File \"C:\\Users\\Sehwan Yoo\\.conda\\envs\\tf1.15\\lib\\site-packages\\tensorflow_estimator\\__init__.py\", line 10, in <module>\n",
      "    from tensorflow_estimator._api.v1 import estimator\n",
      "  File \"C:\\Users\\Sehwan Yoo\\.conda\\envs\\tf1.15\\lib\\site-packages\\tensorflow_estimator\\_api\\v1\\estimator\\__init__.py\", line 10, in <module>\n",
      "    from tensorflow_estimator._api.v1.estimator import experimental\n",
      "  File \"C:\\Users\\Sehwan Yoo\\.conda\\envs\\tf1.15\\lib\\site-packages\\tensorflow_estimator\\_api\\v1\\estimator\\experimental\\__init__.py\", line 10, in <module>\n",
      "    from tensorflow_estimator.python.estimator.canned.dnn import dnn_logit_fn_builder\n",
      "  File \"C:\\Users\\Sehwan Yoo\\.conda\\envs\\tf1.15\\lib\\site-packages\\tensorflow_estimator\\python\\estimator\\canned\\dnn.py\", line 27, in <module>\n",
      "    from tensorflow_estimator.python.estimator import estimator\n",
      "  File \"C:\\Users\\Sehwan Yoo\\.conda\\envs\\tf1.15\\lib\\site-packages\\tensorflow_estimator\\python\\estimator\\estimator.py\", line 36, in <module>\n",
      "    from tensorflow.python.profiler import trace\n",
      "ImportError: cannot import name 'trace' from 'tensorflow.python.profiler' (C:\\Users\\Sehwan Yoo\\.conda\\envs\\tf1.15\\lib\\site-packages\\tensorflow_core\\python\\profiler\\__init__.py)\n",
      "\n",
      "During handling of the above exception, another exception occurred:\n",
      "\n",
      "Traceback (most recent call last):\n",
      "  File \"C:\\Users\\Sehwan Yoo\\.conda\\envs\\tf1.15\\lib\\site-packages\\IPython\\core\\interactiveshell.py\", line 2077, in showtraceback\n",
      "    stb = value._render_traceback_()\n",
      "AttributeError: 'ImportError' object has no attribute '_render_traceback_'\n",
      "\n",
      "During handling of the above exception, another exception occurred:\n",
      "\n",
      "Traceback (most recent call last):\n",
      "  File \"C:\\Users\\Sehwan Yoo\\.conda\\envs\\tf1.15\\lib\\site-packages\\IPython\\core\\ultratb.py\", line 1101, in get_records\n",
      "    return _fixed_getinnerframes(etb, number_of_lines_of_context, tb_offset)\n",
      "  File \"C:\\Users\\Sehwan Yoo\\.conda\\envs\\tf1.15\\lib\\site-packages\\IPython\\core\\ultratb.py\", line 248, in wrapped\n",
      "    return f(*args, **kwargs)\n",
      "  File \"C:\\Users\\Sehwan Yoo\\.conda\\envs\\tf1.15\\lib\\site-packages\\IPython\\core\\ultratb.py\", line 281, in _fixed_getinnerframes\n",
      "    records = fix_frame_records_filenames(inspect.getinnerframes(etb, context))\n",
      "  File \"C:\\Users\\Sehwan Yoo\\.conda\\envs\\tf1.15\\lib\\inspect.py\", line 1502, in getinnerframes\n",
      "    frameinfo = (tb.tb_frame,) + getframeinfo(tb, context)\n",
      "  File \"C:\\Users\\Sehwan Yoo\\.conda\\envs\\tf1.15\\lib\\inspect.py\", line 1460, in getframeinfo\n",
      "    filename = getsourcefile(frame) or getfile(frame)\n",
      "  File \"C:\\Users\\Sehwan Yoo\\.conda\\envs\\tf1.15\\lib\\inspect.py\", line 696, in getsourcefile\n",
      "    if getattr(getmodule(object, filename), '__loader__', None) is not None:\n",
      "  File \"C:\\Users\\Sehwan Yoo\\.conda\\envs\\tf1.15\\lib\\inspect.py\", line 733, in getmodule\n",
      "    if ismodule(module) and hasattr(module, '__file__'):\n",
      "  File \"C:\\Users\\Sehwan Yoo\\.conda\\envs\\tf1.15\\lib\\site-packages\\tensorflow\\__init__.py\", line 50, in __getattr__\n",
      "    module = self._load()\n",
      "  File \"C:\\Users\\Sehwan Yoo\\.conda\\envs\\tf1.15\\lib\\site-packages\\tensorflow\\__init__.py\", line 44, in _load\n",
      "    module = _importlib.import_module(self.__name__)\n",
      "  File \"C:\\Users\\Sehwan Yoo\\.conda\\envs\\tf1.15\\lib\\importlib\\__init__.py\", line 127, in import_module\n",
      "    return _bootstrap._gcd_import(name[level:], package, level)\n",
      "  File \"<frozen importlib._bootstrap>\", line 1006, in _gcd_import\n",
      "  File \"<frozen importlib._bootstrap>\", line 983, in _find_and_load\n",
      "  File \"<frozen importlib._bootstrap>\", line 965, in _find_and_load_unlocked\n",
      "ModuleNotFoundError: No module named 'tensorflow_core.estimator'\n",
      "Traceback (most recent call last):\n",
      "  File \"C:\\Users\\Sehwan Yoo\\.conda\\envs\\tf1.15\\lib\\site-packages\\IPython\\core\\interactiveshell.py\", line 3457, in run_code\n",
      "    exec(code_obj, self.user_global_ns, self.user_ns)\n",
      "  File \"C:\\Users\\SEHWAN~1\\AppData\\Local\\Temp/ipykernel_43336/3479638839.py\", line 1, in <module>\n",
      "    from stable_baselines.common.atari_wrappers import make_atari, wrap_deepmind\n",
      "  File \"C:\\Users\\Sehwan Yoo\\.conda\\envs\\tf1.15\\lib\\site-packages\\stable_baselines\\__init__.py\", line 7, in <module>\n",
      "    from stable_baselines.deepq import DQN\n",
      "  File \"C:\\Users\\Sehwan Yoo\\.conda\\envs\\tf1.15\\lib\\site-packages\\stable_baselines\\deepq\\__init__.py\", line 1, in <module>\n",
      "    from stable_baselines.deepq.policies import MlpPolicy, CnnPolicy, LnMlpPolicy, LnCnnPolicy\n",
      "  File \"C:\\Users\\Sehwan Yoo\\.conda\\envs\\tf1.15\\lib\\site-packages\\stable_baselines\\deepq\\policies.py\", line 2, in <module>\n",
      "    import tensorflow.contrib.layers as tf_layers\n",
      "  File \"C:\\Users\\Sehwan Yoo\\.conda\\envs\\tf1.15\\lib\\site-packages\\tensorflow\\__init__.py\", line 50, in __getattr__\n",
      "    module = self._load()\n",
      "  File \"C:\\Users\\Sehwan Yoo\\.conda\\envs\\tf1.15\\lib\\site-packages\\tensorflow\\__init__.py\", line 44, in _load\n",
      "    module = _importlib.import_module(self.__name__)\n",
      "  File \"C:\\Users\\Sehwan Yoo\\.conda\\envs\\tf1.15\\lib\\importlib\\__init__.py\", line 127, in import_module\n",
      "    return _bootstrap._gcd_import(name[level:], package, level)\n",
      "  File \"C:\\Users\\Sehwan Yoo\\.conda\\envs\\tf1.15\\lib\\site-packages\\tensorflow_core\\contrib\\__init__.py\", line 39, in <module>\n",
      "    from tensorflow.contrib import compiler\n",
      "  File \"C:\\Users\\Sehwan Yoo\\.conda\\envs\\tf1.15\\lib\\site-packages\\tensorflow_core\\contrib\\compiler\\__init__.py\", line 21, in <module>\n",
      "    from tensorflow.contrib.compiler import jit\n",
      "  File \"C:\\Users\\Sehwan Yoo\\.conda\\envs\\tf1.15\\lib\\site-packages\\tensorflow_core\\contrib\\compiler\\__init__.py\", line 22, in <module>\n",
      "    from tensorflow.contrib.compiler import xla\n",
      "  File \"C:\\Users\\Sehwan Yoo\\.conda\\envs\\tf1.15\\lib\\site-packages\\tensorflow_core\\contrib\\compiler\\xla.py\", line 22, in <module>\n",
      "    from tensorflow.python.estimator import model_fn as model_fn_lib\n",
      "  File \"C:\\Users\\Sehwan Yoo\\.conda\\envs\\tf1.15\\lib\\site-packages\\tensorflow_core\\python\\estimator\\model_fn.py\", line 26, in <module>\n",
      "    from tensorflow_estimator.python.estimator import model_fn\n",
      "  File \"C:\\Users\\Sehwan Yoo\\.conda\\envs\\tf1.15\\lib\\site-packages\\tensorflow_estimator\\__init__.py\", line 10, in <module>\n",
      "    from tensorflow_estimator._api.v1 import estimator\n",
      "  File \"C:\\Users\\Sehwan Yoo\\.conda\\envs\\tf1.15\\lib\\site-packages\\tensorflow_estimator\\_api\\v1\\estimator\\__init__.py\", line 10, in <module>\n",
      "    from tensorflow_estimator._api.v1.estimator import experimental\n",
      "  File \"C:\\Users\\Sehwan Yoo\\.conda\\envs\\tf1.15\\lib\\site-packages\\tensorflow_estimator\\_api\\v1\\estimator\\experimental\\__init__.py\", line 10, in <module>\n",
      "    from tensorflow_estimator.python.estimator.canned.dnn import dnn_logit_fn_builder\n",
      "  File \"C:\\Users\\Sehwan Yoo\\.conda\\envs\\tf1.15\\lib\\site-packages\\tensorflow_estimator\\python\\estimator\\canned\\dnn.py\", line 27, in <module>\n",
      "    from tensorflow_estimator.python.estimator import estimator\n",
      "  File \"C:\\Users\\Sehwan Yoo\\.conda\\envs\\tf1.15\\lib\\site-packages\\tensorflow_estimator\\python\\estimator\\estimator.py\", line 36, in <module>\n",
      "    from tensorflow.python.profiler import trace\n",
      "ImportError: cannot import name 'trace' from 'tensorflow.python.profiler' (C:\\Users\\Sehwan Yoo\\.conda\\envs\\tf1.15\\lib\\site-packages\\tensorflow_core\\python\\profiler\\__init__.py)\n",
      "\n",
      "During handling of the above exception, another exception occurred:\n",
      "\n",
      "Traceback (most recent call last):\n",
      "  File \"C:\\Users\\Sehwan Yoo\\.conda\\envs\\tf1.15\\lib\\site-packages\\IPython\\core\\interactiveshell.py\", line 2077, in showtraceback\n",
      "    stb = value._render_traceback_()\n",
      "AttributeError: 'ImportError' object has no attribute '_render_traceback_'\n",
      "\n",
      "During handling of the above exception, another exception occurred:\n",
      "\n",
      "Traceback (most recent call last):\n",
      "  File \"C:\\Users\\Sehwan Yoo\\.conda\\envs\\tf1.15\\lib\\site-packages\\IPython\\core\\interactiveshell.py\", line 3377, in run_ast_nodes\n",
      "    if (await self.run_code(code, result,  async_=asy)):\n",
      "  File \"C:\\Users\\Sehwan Yoo\\.conda\\envs\\tf1.15\\lib\\site-packages\\IPython\\core\\interactiveshell.py\", line 3474, in run_code\n",
      "    self.showtraceback(running_compiled_code=True)\n",
      "  File \"C:\\Users\\Sehwan Yoo\\.conda\\envs\\tf1.15\\lib\\site-packages\\IPython\\core\\interactiveshell.py\", line 2080, in showtraceback\n",
      "    value, tb, tb_offset=tb_offset)\n",
      "  File \"C:\\Users\\Sehwan Yoo\\.conda\\envs\\tf1.15\\lib\\site-packages\\IPython\\core\\ultratb.py\", line 1368, in structured_traceback\n",
      "    self, etype, value, tb, tb_offset, number_of_lines_of_context)\n",
      "  File \"C:\\Users\\Sehwan Yoo\\.conda\\envs\\tf1.15\\lib\\site-packages\\IPython\\core\\ultratb.py\", line 1268, in structured_traceback\n",
      "    self, etype, value, tb, tb_offset, number_of_lines_of_context\n",
      "  File \"C:\\Users\\Sehwan Yoo\\.conda\\envs\\tf1.15\\lib\\site-packages\\IPython\\core\\ultratb.py\", line 1125, in structured_traceback\n",
      "    tb_offset)\n",
      "  File \"C:\\Users\\Sehwan Yoo\\.conda\\envs\\tf1.15\\lib\\site-packages\\IPython\\core\\ultratb.py\", line 1082, in format_exception_as_a_whole\n",
      "    last_unique, recursion_repeat = find_recursion(orig_etype, evalue, records)\n",
      "  File \"C:\\Users\\Sehwan Yoo\\.conda\\envs\\tf1.15\\lib\\site-packages\\IPython\\core\\ultratb.py\", line 382, in find_recursion\n",
      "    return len(records), 0\n",
      "TypeError: object of type 'NoneType' has no len()\n",
      "\n",
      "During handling of the above exception, another exception occurred:\n",
      "\n",
      "Traceback (most recent call last):\n",
      "  File \"C:\\Users\\Sehwan Yoo\\.conda\\envs\\tf1.15\\lib\\site-packages\\IPython\\core\\interactiveshell.py\", line 2077, in showtraceback\n",
      "    stb = value._render_traceback_()\n",
      "AttributeError: 'TypeError' object has no attribute '_render_traceback_'\n",
      "\n",
      "During handling of the above exception, another exception occurred:\n",
      "\n",
      "Traceback (most recent call last):\n",
      "  File \"C:\\Users\\Sehwan Yoo\\.conda\\envs\\tf1.15\\lib\\site-packages\\IPython\\core\\ultratb.py\", line 1101, in get_records\n",
      "    return _fixed_getinnerframes(etb, number_of_lines_of_context, tb_offset)\n",
      "  File \"C:\\Users\\Sehwan Yoo\\.conda\\envs\\tf1.15\\lib\\site-packages\\IPython\\core\\ultratb.py\", line 248, in wrapped\n",
      "    return f(*args, **kwargs)\n",
      "  File \"C:\\Users\\Sehwan Yoo\\.conda\\envs\\tf1.15\\lib\\site-packages\\IPython\\core\\ultratb.py\", line 281, in _fixed_getinnerframes\n",
      "    records = fix_frame_records_filenames(inspect.getinnerframes(etb, context))\n",
      "  File \"C:\\Users\\Sehwan Yoo\\.conda\\envs\\tf1.15\\lib\\inspect.py\", line 1502, in getinnerframes\n",
      "    frameinfo = (tb.tb_frame,) + getframeinfo(tb, context)\n",
      "  File \"C:\\Users\\Sehwan Yoo\\.conda\\envs\\tf1.15\\lib\\inspect.py\", line 1460, in getframeinfo\n",
      "    filename = getsourcefile(frame) or getfile(frame)\n",
      "  File \"C:\\Users\\Sehwan Yoo\\.conda\\envs\\tf1.15\\lib\\inspect.py\", line 696, in getsourcefile\n",
      "    if getattr(getmodule(object, filename), '__loader__', None) is not None:\n",
      "  File \"C:\\Users\\Sehwan Yoo\\.conda\\envs\\tf1.15\\lib\\inspect.py\", line 733, in getmodule\n",
      "    if ismodule(module) and hasattr(module, '__file__'):\n",
      "  File \"C:\\Users\\Sehwan Yoo\\.conda\\envs\\tf1.15\\lib\\site-packages\\tensorflow\\__init__.py\", line 50, in __getattr__\n",
      "    module = self._load()\n",
      "  File \"C:\\Users\\Sehwan Yoo\\.conda\\envs\\tf1.15\\lib\\site-packages\\tensorflow\\__init__.py\", line 44, in _load\n",
      "    module = _importlib.import_module(self.__name__)\n",
      "  File \"C:\\Users\\Sehwan Yoo\\.conda\\envs\\tf1.15\\lib\\importlib\\__init__.py\", line 127, in import_module\n",
      "    return _bootstrap._gcd_import(name[level:], package, level)\n",
      "  File \"<frozen importlib._bootstrap>\", line 1006, in _gcd_import\n",
      "  File \"<frozen importlib._bootstrap>\", line 983, in _find_and_load\n",
      "  File \"<frozen importlib._bootstrap>\", line 965, in _find_and_load_unlocked\n",
      "ModuleNotFoundError: No module named 'tensorflow_core.estimator'\n",
      "Traceback (most recent call last):\n",
      "  File \"C:\\Users\\Sehwan Yoo\\.conda\\envs\\tf1.15\\lib\\site-packages\\IPython\\core\\interactiveshell.py\", line 3457, in run_code\n",
      "    exec(code_obj, self.user_global_ns, self.user_ns)\n",
      "  File \"C:\\Users\\SEHWAN~1\\AppData\\Local\\Temp/ipykernel_43336/3479638839.py\", line 1, in <module>\n",
      "    from stable_baselines.common.atari_wrappers import make_atari, wrap_deepmind\n",
      "  File \"C:\\Users\\Sehwan Yoo\\.conda\\envs\\tf1.15\\lib\\site-packages\\stable_baselines\\__init__.py\", line 7, in <module>\n",
      "    from stable_baselines.deepq import DQN\n",
      "  File \"C:\\Users\\Sehwan Yoo\\.conda\\envs\\tf1.15\\lib\\site-packages\\stable_baselines\\deepq\\__init__.py\", line 1, in <module>\n",
      "    from stable_baselines.deepq.policies import MlpPolicy, CnnPolicy, LnMlpPolicy, LnCnnPolicy\n",
      "  File \"C:\\Users\\Sehwan Yoo\\.conda\\envs\\tf1.15\\lib\\site-packages\\stable_baselines\\deepq\\policies.py\", line 2, in <module>\n",
      "    import tensorflow.contrib.layers as tf_layers\n",
      "  File \"C:\\Users\\Sehwan Yoo\\.conda\\envs\\tf1.15\\lib\\site-packages\\tensorflow\\__init__.py\", line 50, in __getattr__\n",
      "    module = self._load()\n",
      "  File \"C:\\Users\\Sehwan Yoo\\.conda\\envs\\tf1.15\\lib\\site-packages\\tensorflow\\__init__.py\", line 44, in _load\n",
      "    module = _importlib.import_module(self.__name__)\n",
      "  File \"C:\\Users\\Sehwan Yoo\\.conda\\envs\\tf1.15\\lib\\importlib\\__init__.py\", line 127, in import_module\n",
      "    return _bootstrap._gcd_import(name[level:], package, level)\n",
      "  File \"C:\\Users\\Sehwan Yoo\\.conda\\envs\\tf1.15\\lib\\site-packages\\tensorflow_core\\contrib\\__init__.py\", line 39, in <module>\n",
      "    from tensorflow.contrib import compiler\n",
      "  File \"C:\\Users\\Sehwan Yoo\\.conda\\envs\\tf1.15\\lib\\site-packages\\tensorflow_core\\contrib\\compiler\\__init__.py\", line 21, in <module>\n",
      "    from tensorflow.contrib.compiler import jit\n",
      "  File \"C:\\Users\\Sehwan Yoo\\.conda\\envs\\tf1.15\\lib\\site-packages\\tensorflow_core\\contrib\\compiler\\__init__.py\", line 22, in <module>\n",
      "    from tensorflow.contrib.compiler import xla\n",
      "  File \"C:\\Users\\Sehwan Yoo\\.conda\\envs\\tf1.15\\lib\\site-packages\\tensorflow_core\\contrib\\compiler\\xla.py\", line 22, in <module>\n",
      "    from tensorflow.python.estimator import model_fn as model_fn_lib\n",
      "  File \"C:\\Users\\Sehwan Yoo\\.conda\\envs\\tf1.15\\lib\\site-packages\\tensorflow_core\\python\\estimator\\model_fn.py\", line 26, in <module>\n",
      "    from tensorflow_estimator.python.estimator import model_fn\n",
      "  File \"C:\\Users\\Sehwan Yoo\\.conda\\envs\\tf1.15\\lib\\site-packages\\tensorflow_estimator\\__init__.py\", line 10, in <module>\n",
      "    from tensorflow_estimator._api.v1 import estimator\n",
      "  File \"C:\\Users\\Sehwan Yoo\\.conda\\envs\\tf1.15\\lib\\site-packages\\tensorflow_estimator\\_api\\v1\\estimator\\__init__.py\", line 10, in <module>\n",
      "    from tensorflow_estimator._api.v1.estimator import experimental\n",
      "  File \"C:\\Users\\Sehwan Yoo\\.conda\\envs\\tf1.15\\lib\\site-packages\\tensorflow_estimator\\_api\\v1\\estimator\\experimental\\__init__.py\", line 10, in <module>\n",
      "    from tensorflow_estimator.python.estimator.canned.dnn import dnn_logit_fn_builder\n",
      "  File \"C:\\Users\\Sehwan Yoo\\.conda\\envs\\tf1.15\\lib\\site-packages\\tensorflow_estimator\\python\\estimator\\canned\\dnn.py\", line 27, in <module>\n",
      "    from tensorflow_estimator.python.estimator import estimator\n",
      "  File \"C:\\Users\\Sehwan Yoo\\.conda\\envs\\tf1.15\\lib\\site-packages\\tensorflow_estimator\\python\\estimator\\estimator.py\", line 36, in <module>\n",
      "    from tensorflow.python.profiler import trace\n",
      "ImportError: cannot import name 'trace' from 'tensorflow.python.profiler' (C:\\Users\\Sehwan Yoo\\.conda\\envs\\tf1.15\\lib\\site-packages\\tensorflow_core\\python\\profiler\\__init__.py)\n",
      "\n",
      "During handling of the above exception, another exception occurred:\n",
      "\n",
      "Traceback (most recent call last):\n",
      "  File \"C:\\Users\\Sehwan Yoo\\.conda\\envs\\tf1.15\\lib\\site-packages\\IPython\\core\\interactiveshell.py\", line 2077, in showtraceback\n",
      "    stb = value._render_traceback_()\n",
      "AttributeError: 'ImportError' object has no attribute '_render_traceback_'\n",
      "\n",
      "During handling of the above exception, another exception occurred:\n",
      "\n",
      "Traceback (most recent call last):\n",
      "  File \"C:\\Users\\Sehwan Yoo\\.conda\\envs\\tf1.15\\lib\\site-packages\\IPython\\core\\interactiveshell.py\", line 3377, in run_ast_nodes\n",
      "    if (await self.run_code(code, result,  async_=asy)):\n",
      "  File \"C:\\Users\\Sehwan Yoo\\.conda\\envs\\tf1.15\\lib\\site-packages\\IPython\\core\\interactiveshell.py\", line 3474, in run_code\n",
      "    self.showtraceback(running_compiled_code=True)\n",
      "  File \"C:\\Users\\Sehwan Yoo\\.conda\\envs\\tf1.15\\lib\\site-packages\\IPython\\core\\interactiveshell.py\", line 2080, in showtraceback\n",
      "    value, tb, tb_offset=tb_offset)\n",
      "  File \"C:\\Users\\Sehwan Yoo\\.conda\\envs\\tf1.15\\lib\\site-packages\\IPython\\core\\ultratb.py\", line 1368, in structured_traceback\n",
      "    self, etype, value, tb, tb_offset, number_of_lines_of_context)\n",
      "  File \"C:\\Users\\Sehwan Yoo\\.conda\\envs\\tf1.15\\lib\\site-packages\\IPython\\core\\ultratb.py\", line 1268, in structured_traceback\n",
      "    self, etype, value, tb, tb_offset, number_of_lines_of_context\n",
      "  File \"C:\\Users\\Sehwan Yoo\\.conda\\envs\\tf1.15\\lib\\site-packages\\IPython\\core\\ultratb.py\", line 1125, in structured_traceback\n",
      "    tb_offset)\n",
      "  File \"C:\\Users\\Sehwan Yoo\\.conda\\envs\\tf1.15\\lib\\site-packages\\IPython\\core\\ultratb.py\", line 1082, in format_exception_as_a_whole\n",
      "    last_unique, recursion_repeat = find_recursion(orig_etype, evalue, records)\n",
      "  File \"C:\\Users\\Sehwan Yoo\\.conda\\envs\\tf1.15\\lib\\site-packages\\IPython\\core\\ultratb.py\", line 382, in find_recursion\n",
      "    return len(records), 0\n",
      "TypeError: object of type 'NoneType' has no len()\n",
      "\n",
      "During handling of the above exception, another exception occurred:\n",
      "\n",
      "Traceback (most recent call last):\n",
      "  File \"C:\\Users\\Sehwan Yoo\\.conda\\envs\\tf1.15\\lib\\site-packages\\IPython\\core\\interactiveshell.py\", line 2077, in showtraceback\n",
      "    stb = value._render_traceback_()\n",
      "AttributeError: 'TypeError' object has no attribute '_render_traceback_'\n",
      "\n",
      "During handling of the above exception, another exception occurred:\n",
      "\n",
      "Traceback (most recent call last):\n",
      "  File \"C:\\Users\\Sehwan Yoo\\.conda\\envs\\tf1.15\\lib\\site-packages\\IPython\\core\\interactiveshell.py\", line 2960, in _run_cell\n",
      "    return runner(coro)\n",
      "  File \"C:\\Users\\Sehwan Yoo\\.conda\\envs\\tf1.15\\lib\\site-packages\\IPython\\core\\async_helpers.py\", line 78, in _pseudo_sync_runner\n",
      "    coro.send(None)\n",
      "  File \"C:\\Users\\Sehwan Yoo\\.conda\\envs\\tf1.15\\lib\\site-packages\\IPython\\core\\interactiveshell.py\", line 3186, in run_cell_async\n",
      "    interactivity=interactivity, compiler=compiler, result=result)\n",
      "  File \"C:\\Users\\Sehwan Yoo\\.conda\\envs\\tf1.15\\lib\\site-packages\\IPython\\core\\interactiveshell.py\", line 3396, in run_ast_nodes\n",
      "    self.showtraceback()\n",
      "  File \"C:\\Users\\Sehwan Yoo\\.conda\\envs\\tf1.15\\lib\\site-packages\\IPython\\core\\interactiveshell.py\", line 2080, in showtraceback\n",
      "    value, tb, tb_offset=tb_offset)\n",
      "  File \"C:\\Users\\Sehwan Yoo\\.conda\\envs\\tf1.15\\lib\\site-packages\\IPython\\core\\ultratb.py\", line 1368, in structured_traceback\n",
      "    self, etype, value, tb, tb_offset, number_of_lines_of_context)\n",
      "  File \"C:\\Users\\Sehwan Yoo\\.conda\\envs\\tf1.15\\lib\\site-packages\\IPython\\core\\ultratb.py\", line 1268, in structured_traceback\n",
      "    self, etype, value, tb, tb_offset, number_of_lines_of_context\n",
      "  File \"C:\\Users\\Sehwan Yoo\\.conda\\envs\\tf1.15\\lib\\site-packages\\IPython\\core\\ultratb.py\", line 1143, in structured_traceback\n",
      "    chained_exceptions_tb_offset)\n",
      "  File \"C:\\Users\\Sehwan Yoo\\.conda\\envs\\tf1.15\\lib\\site-packages\\IPython\\core\\ultratb.py\", line 1082, in format_exception_as_a_whole\n",
      "    last_unique, recursion_repeat = find_recursion(orig_etype, evalue, records)\n",
      "  File \"C:\\Users\\Sehwan Yoo\\.conda\\envs\\tf1.15\\lib\\site-packages\\IPython\\core\\ultratb.py\", line 382, in find_recursion\n",
      "    return len(records), 0\n",
      "TypeError: object of type 'NoneType' has no len()\n",
      "\n",
      "During handling of the above exception, another exception occurred:\n",
      "\n",
      "Traceback (most recent call last):\n",
      "  File \"C:\\Users\\Sehwan Yoo\\.conda\\envs\\tf1.15\\lib\\site-packages\\IPython\\core\\interactiveshell.py\", line 2077, in showtraceback\n",
      "    stb = value._render_traceback_()\n",
      "AttributeError: 'TypeError' object has no attribute '_render_traceback_'\n",
      "\n",
      "During handling of the above exception, another exception occurred:\n",
      "\n",
      "Traceback (most recent call last):\n",
      "  File \"C:\\Users\\Sehwan Yoo\\.conda\\envs\\tf1.15\\lib\\site-packages\\IPython\\core\\ultratb.py\", line 1101, in get_records\n",
      "    return _fixed_getinnerframes(etb, number_of_lines_of_context, tb_offset)\n",
      "  File \"C:\\Users\\Sehwan Yoo\\.conda\\envs\\tf1.15\\lib\\site-packages\\IPython\\core\\ultratb.py\", line 248, in wrapped\n",
      "    return f(*args, **kwargs)\n",
      "  File \"C:\\Users\\Sehwan Yoo\\.conda\\envs\\tf1.15\\lib\\site-packages\\IPython\\core\\ultratb.py\", line 281, in _fixed_getinnerframes\n",
      "    records = fix_frame_records_filenames(inspect.getinnerframes(etb, context))\n",
      "  File \"C:\\Users\\Sehwan Yoo\\.conda\\envs\\tf1.15\\lib\\inspect.py\", line 1502, in getinnerframes\n",
      "    frameinfo = (tb.tb_frame,) + getframeinfo(tb, context)\n",
      "  File \"C:\\Users\\Sehwan Yoo\\.conda\\envs\\tf1.15\\lib\\inspect.py\", line 1460, in getframeinfo\n",
      "    filename = getsourcefile(frame) or getfile(frame)\n",
      "  File \"C:\\Users\\Sehwan Yoo\\.conda\\envs\\tf1.15\\lib\\inspect.py\", line 696, in getsourcefile\n",
      "    if getattr(getmodule(object, filename), '__loader__', None) is not None:\n",
      "  File \"C:\\Users\\Sehwan Yoo\\.conda\\envs\\tf1.15\\lib\\inspect.py\", line 733, in getmodule\n",
      "    if ismodule(module) and hasattr(module, '__file__'):\n",
      "  File \"C:\\Users\\Sehwan Yoo\\.conda\\envs\\tf1.15\\lib\\site-packages\\tensorflow\\__init__.py\", line 50, in __getattr__\n",
      "    module = self._load()\n",
      "  File \"C:\\Users\\Sehwan Yoo\\.conda\\envs\\tf1.15\\lib\\site-packages\\tensorflow\\__init__.py\", line 44, in _load\n",
      "    module = _importlib.import_module(self.__name__)\n",
      "  File \"C:\\Users\\Sehwan Yoo\\.conda\\envs\\tf1.15\\lib\\importlib\\__init__.py\", line 127, in import_module\n",
      "    return _bootstrap._gcd_import(name[level:], package, level)\n",
      "  File \"<frozen importlib._bootstrap>\", line 1006, in _gcd_import\n",
      "  File \"<frozen importlib._bootstrap>\", line 983, in _find_and_load\n",
      "  File \"<frozen importlib._bootstrap>\", line 965, in _find_and_load_unlocked\n",
      "ModuleNotFoundError: No module named 'tensorflow_core.estimator'\n"
     ]
    }
   ],
   "source": [
    "from stable_baselines.common.atari_wrappers import make_atari, wrap_deepmind\n",
    "import numpy as np\n",
    "import tensorflow as tf\n",
    "from tensorflow import keras\n",
    "from tensorflow.keras import layers\n",
    "\n",
    "# Configuration paramaters for the whole setup\n",
    "seed = 42\n",
    "gamma = 0.99  # Discount factor for past rewards\n",
    "epsilon = 1.0  # Epsilon greedy parameter\n",
    "epsilon_min = 0.1  # Minimum epsilon greedy parameter\n",
    "epsilon_max = 1.0  # Maximum epsilon greedy parameter\n",
    "epsilon_interval = (\n",
    "    epsilon_max - epsilon_min\n",
    ")  # Rate at which to reduce chance of random action being taken\n",
    "batch_size = 32  # Size of batch taken from replay buffer\n",
    "max_steps_per_episode = 10000\n",
    "\n",
    "# Use the Baseline Atari environment because of Deepmind helper functions\n",
    "env = make_atari(\"BreakoutNoFrameskip-v4\")\n",
    "# Warp the frames, grey scale, stake four frame and scale to smaller ratio\n",
    "env = wrap_deepmind(env, frame_stack=True, scale=True)\n",
    "env.seed(seed)"
   ]
  },
  {
   "cell_type": "code",
   "execution_count": null,
   "metadata": {},
   "outputs": [],
   "source": []
  }
 ],
 "metadata": {
  "interpreter": {
   "hash": "ddde1e1c6000e1d3034bec6257a8f68bed92c50866ae12a8382b98f1add9b5c2"
  },
  "kernelspec": {
   "display_name": "Python 3.9.5 64-bit",
   "language": "python",
   "name": "python3"
  },
  "language_info": {
   "codemirror_mode": {
    "name": "ipython",
    "version": 3
   },
   "file_extension": ".py",
   "mimetype": "text/x-python",
   "name": "python",
   "nbconvert_exporter": "python",
   "pygments_lexer": "ipython3",
   "version": "3.7.11"
  },
  "orig_nbformat": 4
 },
 "nbformat": 4,
 "nbformat_minor": 2
}
